Workbook

Sheet escala credit risk rating
C4: AAA | D4: máxima calificación crediticia (más seguro)
C5: AA+
C6: AA
C7: AA-
C8: A+
C9: A
C10: A-
C11: BBB+
C12: BBB
C13: BBB- | D13: de aquí hacia arriba es grado de inversión (investment grade), y hacia abajo es grado especulativo (high yield)
C14: BB+
C15: BB
C16: BB-
C17: B+
C18: B
C19: B-
C20: CCC | D20: calificación crediticia más baja (más riesgosa, a un paso del default)
C21: D

Sheet factores LCR y NSFR
B2: LCR HQLA | C2: Tipo de activo | D2: Ponderación
B3: Nivel 1 | C3: Efectivo y reservas en el banco central | D3: 1 | E3: sin haircut
B4: Nivel 1 | C4: Bonos gubernamentales < 1 año o duración menor a 1 | D4: 1 | E4: sin haircut
B5: Nivel 2A | C5: Bonos soberanos >1 año | D5: 0.85 | E5: haircut del 15%
B6: Nivel 2A | C6: Bonos corporativos calif AA- o superior | D6: 0.85 | E6: haircut del 15%
B7: Nivel 2B | C7: Bonos corporativos calif BBB- a A+ | D7: 0.5 | E7: haircut del 50%
A10: LCR | B10: Salidas (pasivos) factores de run-off a 30 días
C11: Depósitos minoristas core (vista y plazo) | D11: 0.03
C12: Depósitos minoristas menos estables (vista y plazo) | D12: 0.1
C13: Depósitos operacionales de empresas (vista y plazo) | D13: 0.25
C14: Depósitos no operacionales de empresas (vista y plazo) | D14: 0.4
C15: Depósitos no operacioneles de financieras (vista y plazo) | D15: 1
C17: Fondeo mayorista garantizado con HQLA Nivel 1 | D17: 0
C18: Fondeo mayorista garantizado con HQLA Nivel 2A contraparte no financiera | D18: 0.15
C19: Fondeo mayorista garantizado con HQLA Nivel 2A contraparte financiera | D19: 0.25
C20: Fondeo mayorista sin colateral (sin garantía) | D20: 1
B23: NSFR Factores para ASF (available stable funding)
C24: Capital Tier 1 y Tier 2 | D24: 1 | E24: lo más estable y disponible
C25: Pasivos con plazo residual mayor a 1 año | D25: 1 | E25: bonos emitidos, deuda subordinada
C26: Depósitos minoristas estables (core) | D26: 0.95 | E26: alta retención histórica (estadísticas)
C27: Depósitos minoristas menos estables (volátiles) | D27: 0.9 | E27: menor retención esperada
C28: Depósitos operacionales de empresas no financieras | D28: 0.75 | E28: relación operacional con el banco parcialmente estable
C29: Depósitos no operacionales de empresas no financieras | D29: 0 | E29: altamente volátil, no aporta fondeo estable
C30: Depósitos operacionales de empresas financieras | D30: 0.5 | E30: relación operacional con el banco parcialmente estable
C31: Depósitos no operacionales de empresas financieras | D31: 0 | E31: altamente volátil, no aporta fondeo estable
C32: Fondeo mayorista contrapartes no financieras con colateral | D32: 0.6 | E32: estabilidad relativa
C33: Fondeo mayorista contrapartes financieras con colateral | D33: 0.4 | E33: estabilidad relativa
C34: Fondeo mayorista sin colateral | D34: 0 | E34: altamente volátil, no aporta fondeo estable
B36: NSFR Factores para RSF (required stable funding)
C37: Efectivo y depósitos en el banco central | D37: 0
C38: HQLA nivel 1 | D38: 0.05
C39: HQLA nivel 2A | D39: 0.15
C40: HQLA nivel 2B | D40: 0.5
C41: Hipotecarios | D41: 0.65
C42: Créditos a consumo | D42: 0.5
C43: Créditos PYME | D43: 0.65
C44: Créditos a empresas no financieras (corporativos) largo plazo | D44: 0.65
C45: Créditos a instituciones financieras (largo plazo) | D45: 1

Sheet notas importantes
B2: (a) Para el Banco del Pacífico dado su enfoque en personas físicas (minorista) el 60% de sus depósitos se consideran estables o core y el 40% se consideran volátiles o menos estables
B3: mientras que para el Banco del Golfo dado su enfoque más en personas morales, el 30% de esos depósitos se consideran estables o core y el 70% se consideran menos estables
B5: (b) Para el Pacífico, el 20% de esos depósitos se consideran "operacionales" de empresa y el 80% se consideran "no operacionales" de empresa
B6: Para el Golfo, el 70% de esos depósitos son considerados "operacionales" de empresa y el 30% "no operacionales" de empresa
B8: (c) las contrapartes en el fondeo mayorista son empresas financieras, algunos con colateral y otros sin colateral
B9: En el caso de Banco del Pacífico, todo es con contrapartes financieras, la mitad con colateral Nivel 1 y la otra mitad sin colateral
B10: En el caso de Banco del Golfo, el 50% es con contrapartes financieras sin garantía, otro 30% con contrapartes financieras con colateral Nivel 2A y 20% con contrapartes no financieras con colateral Nivel 1
B12: (d) El Capital Tier 1 son principalmente 3 componentes: capital aportado por los socios, capital ganando conocido como utilidades retenidas, reservas de capital
B14: (e) El Capital Tier 2 son principalmente 2 componentes: bonos perpetuos (sin vencimiento) pero que pagan un cupón trimestral o semestral, y bonos convertibles a acciones (Contingent Convertibles)

Sheet balances (banking book)
B3: cifras en millones de pesos | C3: Banco del Pacífico | D3: Banco del Golfo
B4: Efectivo y reservas en el banco central | C4: 450 | D4: 240 | E4: en México no reciben una tasa como sucede en US (IORB, interest rate on reserve balances)
B5: Títulos conservados a vencimiento | C5: =SUM(C6:C10) -> 670 | D5: =SUM(D6:D10) -> 980
B6: Bonos gubernamentales < 1 año (Nivel 1 para HQLA) | C6: 180 | D6: 160 | E6: tasa promedio 7.5%, duración modificada 0.2
B7: Bondes 1-5 años (Nivel 1 para HQLA) | C7: 240 | D7: 120 | E7: tasa variable spread promedio de 19 basis, duración modificada 0.08
B8: Bonos M 1-5 años (Nivel 2A para HQLA) | C8: 150 | D8: 300 | E8: tasa fija promedio del 8.5%, duración modificada 2.4
B9: Bonos corporativos calif AA- o superior tasa fija (Nivel 2A para HQLA) | C9: 100 | D9: 250 | E9: tasa fija promedio del 9%, duración modificada 3.2
B10: Bonos corporativos calif BBB- a A+ tasa fija (nivel 2B para HQLA) | C10: 0 | D10: 150 | E10: tasa fija promedio del 9.5%, duración modificada 2.9
B11: Cartera de crédito | C11: =SUM(C12:C16) -> 6500 | D11: =SUM(D12:D16) -> 6500
B12: Hipotecario | C12: 1500 | D12: 900 | E12: tasa fija promedio del 10.75% para el banco del Pacífico y del 11.50% para el banco del Golfo, duración modificada 8.3 para ambos
B13: Consumo (tarjetas de crédito, de nómina, personales) | C13: 2500 | D13: 1700 | E13: el 60% del Pacífico es tarjetas a TIIE+36%, el resto del Pacífico es fija promedio 19%, para el Golfo el 50% es tarjeta a TIIE+42% y lo demás es fija promedio 24%
B14: PYMES | C14: 800 | D14: 600 | E14: tasa variable promedio de TIIE+9% para el banco del Pacífico y TIIE+12% para el banco del Golfo
B15: Corporativo (grandes empresas) | C15: 1200 | D15: 1900 | E15: tasa variable promedio de TIIE+4% para el banco del Pacífico y TIIE+3% para el banco del Golfo
B16: Instituciones Financieras (sofoms, sofipos, sapis, otros bancos) | C16: 500 | D16: 1400 | E16: tasa variable promedio de TIIE+3% para el banco del Pacífico y TIIE+2.5% para el banco del Golfo
B17: Activos Fijos | C17: 330 | D17: 270
B18: Otros activos | C18: 48 | D18: 64
B19: TOTAL ACTIVO | C19: =C4+C5+C11+C17+C18 -> 7998 | D19: =D4+D5+D11+D17+D18 -> 8054
B20: Depósitos a la vista | C20: =C21+C22 -> 2700 | D20: =D21+D22 -> 3200 | E20: las tasas que pagan por depósitos a la vista, las actualizan en la medida que se mueve la tasa objetivo del banco central por un factor de 0.5
B21: Minoristas (retail)a | C21: 2100 | D21: 1400 | E21: han tenido que empezar a pagar en función del saldo promedio y de acuerdo al monto, Pacífico paga promedio ponderado 4% vs. 3% del Golfo
B22: De empresasb | C22: 600 | D22: 1800 | E22: misma situación dada la competencia de los neobancos, Pacífico paga en promedio 4% vs 5% del Golfo
B23: Depósitos a plazo | C23: =C24+C25 -> 2300 | D23: =D24+D25 -> 2300
B24: Minoristas (retail) | C24: 1900 | D24: 1200 | E24: Pacífico paga tasa promedio del 5% mientras que Golfo paga 4%, repricing mitad mensual y mitad trimestral
B25: De empresas | C25: 400 | D25: 1100 | E25: Pacífico paga tasa ponderada de 5.25% mientras que Golfo paga 6%, repricing 3/4 partes mensual y 1/4 parte trimestral
B26: Fondeo mayoristac | C26: 750 | D26: 900 | E26: tasa promedio 6.5% el Pacífico y 6.75% el Golfo, repricing mitad semanal y mitad mensual
B27: Bonos emitidos con vencimiento < 1 año | C27: 400 | D27: 0
B28: Bonos emitidos con vencimiento 1-5 años | C28: 1000 | D28: 500 | E28: El cupón del Pacífico es 10% duración modificada 2.3, el cupón del Golfo es TIIE+1.25% duración modificada 0.08
B29: Bonos emitidos con vencimiento 5-10 años | C29: 0 | D29: 500 | E29: El cupón del Golfo es 8.75% duración modificada 6.4
B30: TOTAL PASIVO | C30: =C20+C23+C26+C27+C28+C29 -> 7150 | D30: =D20+D23+D26+D27+D28+D29 -> 7400
B31: Capital Tier 1d | C31: 848 | D31: 654
B32: Capital Tier 2e | C32: 0 | D32: 0
B33: TOTAL CAPITAL | C33: =C31+C32 -> 848 | D33: =D31+D32 -> 654
B34: TOTAL PASIVO Y CAPITAL | C34: =C30+C33 -> 7998 | D34: =D30+D33 -> 8054

Sheet Preguntas
B2: Riesgo de Liquidez a corto plazo: LCR
B3: ¿Cuál es el LCR de cada banco? Cumplen con el requisito regulario (mayor a 1.0) ? En caso de que no ¿cómo lo arreglarías?
B5: HQLA | F5: FACTOR | G5: MONTOS FACTORIZADOS
B6: ='balances (banking book)'!B4 -> Efectivo y reservas en el banco central | F6: 1 | G6: ='balances (banking book)'!C4 -> 450 | H6: ='balances (banking book)'!D4 -> 240
B7: {='factores LCR y NSFR'!C3:C7} -> Efectivo y reservas en el banco central | F7: ='factores LCR y NSFR'!D3 -> 1 | G7: ='balances (banking book)'!C6*'factores LCR y NSFR'!D3 -> 180 | H7: ='balances (banking book)'!D6*'factores LCR y NSFR'!D3 -> 160
B8: Bonos gubernamentales < 1 año o duración menor a 1 | F8: ='factores LCR y NSFR'!D4 -> 1 | G8: ='balances (banking book)'!C7*'factores LCR y NSFR'!D4 -> 240 | H8: ='balances (banking book)'!D7*'factores LCR y NSFR'!D4 -> 120
B9: Bonos soberanos >1 año | F9: ='factores LCR y NSFR'!D5 -> 0.85 | G9: ='balances (banking book)'!C8*'factores LCR y NSFR'!D5 -> 127.5 | H9: ='balances (banking book)'!D8*'factores LCR y NSFR'!D5 -> 255
B10: Bonos corporativos calif AA- o superior | F10: ='factores LCR y NSFR'!D6 -> 0.85 | G10: ='balances (banking book)'!C9*'factores LCR y NSFR'!D6 -> 85 | H10: ='balances (banking book)'!D9*'factores LCR y NSFR'!D6 -> 212.5
B11: Bonos corporativos calif BBB- a A+ | F11: ='factores LCR y NSFR'!D7 -> 0.5 | G11: ='balances (banking book)'!C10*'factores LCR y NSFR'!D7 -> 0 | H11: ='balances (banking book)'!D10*'factores LCR y NSFR'!D7 -> 75
F12: TOTAL | G12: =SUM(G6:G11) -> 1082.5 | H12: =SUM(H6:H11) -> 1062.5
B14: SALIDAS NETAS DE EFECTIVO
H15: MONTOS | K15: MONTOS FACTORIZADOS
B16: Depósitos minoristas core (vista) | F16: 0.03 | H16: ='balances (banking book)'!C21*0.6 -> 1260 | K16: =H16*F16 -> 37.8
B17: Depósitos minoristas menos estables (vista) | F17: 0.1 | H17: ='balances (banking book)'!C21*0.4 -> 840 | K17: =H17*F17 -> 84
B19: Depósitos minoristas core (plazo) | F19: 0.03 | H19: ='balances (banking book)'!C24*0.6 -> 1140 | K19: =H19*F19 -> 34.2
B20: Depósitos minoristas menos estables (plazo) | F20: 0.1 | H20: ='balances (banking book)'!C24*0.4 -> 760 | K20: =H20*F20 -> 76
B22: Depósitos operacionales de empresas (vista) | F22: 0.25 | H22: ='balances (banking book)'!C22*0.2 -> 120 | K22: =H22*F22 -> 30
B23: Depósitos no operacionales de empresas (vista) | F23: 0.4 | H23: ='balances (banking book)'!C22*0.8 -> 480 | K23: =H23*F23 -> 192
B25: Depósitos operacionales de empresas (plazo) | F25: 0.25 | H25: ='balances (banking book)'!C25*0.2 -> 80 | K25: =H25*F25 -> 20
B26: Depósitos no operacionales de empresas (plazo) | F26: 0.4 | H26: ='balances (banking book)'!C25*0.8 -> 320 | K26: =H26*F26 -> 128
B28: Fondeo mayorista garantizado con HQLA Nivel 1 | F28: 0 | H28: ='balances (banking book)'!C26*0.5 -> 375 | K28: =H28*F28 -> 0
B29: Fondeo mayorista garantizado con HQLA Nivel 2A contraparte no financiera | F29: 0.15 | K29: =H29*F29 -> 0
B30: Fondeo mayorista garantizado con HQLA Nivel 2A contraparte financiera | F30: 0.25 | K30: =H30*F30 -> 0
B31: Fondeo mayorista sin colateral (sin garantía) | F31: 1 | H31: ='balances (banking book)'!C26*0.5 -> 375 | K31: =H31*F31 -> 375
J32: TOTAL | K32: =SUM(K16:K31) -> 977
B34: LCR | C34: =G12/K32 -> 1.1079836
B36: Riesgo de Liquidez a largo plazo: NSFR
B37: ¿Cuál es el NSFR de cada banco? Cumplen con la regulación (mayor a 1.0) ? En caso contrario ¿qué propones para corregirlo?
B39: ASF | H39: MONTOS | K39: MONTOS FACTORIZADOS
B40: Capital Tier 1 y Tier 2 | F40: 1 | H40: ='balances (banking book)'!C31+'balances (banking book)'!C32 -> 848 | K40: =H40*F40 -> 848
B41: Pasivos con plazo residual mayor a 1 año | F41: 1 | H41: ='balances (banking book)'!C28+'balances (banking book)'!C29 -> 1000 | K41: =H41*F41 -> 1000
B42: Depósitos minoristas estables (core) | F42: 0.95 | H42: =H16+H19 -> 2400 | K42: =H42*F42 -> 2280
B43: Depósitos minoristas menos estables (volátiles) | F43: 0.9 | H43: =H17+H20 -> 1600 | K43: =H43*F43 -> 1440
B44: Depósitos operacionales de empresas no financieras | F44: 0.75 | H44: =H22+H25 -> 200 | K44: =H44*F44 -> 150
B45: Depósitos no operacionales de empresas no financieras | F45: 0 | H45: =H23+H26 -> 800 | K45: =H45*F45 -> 0
B46: Depósitos operacionales de empresas financieras | F46: 0.5 | H46: 0 | K46: =H46*F46 -> 0
B47: Depósitos no operacionales de empresas financieras | F47: 0 | H47: 0 | K47: =H47*F47 -> 0
B48: Fondeo mayorista contrapartes no financieras con colateral | F48: 0.6 | H48: 0 | K48: =H48*F48 -> 0
B49: Fondeo mayorista contrapartes financieras con colateral | F49: 0.4 | H49: =H28 -> 375 | K49: =H49*F49 -> 150
B50: Fondeo mayorista sin colateral | F50: 0 | H50: =H31 -> 375 | K50: =H50*F50 -> 0
...

Sheet NII
B2: cifras en millones de pesos | C2: Banco del Pacífico | D2: Banco del Golfo
B3: Efectivo y reservas en el banco central | C3: 450 | D3: 240 | E3: 0 | F3: =E3*C3 -> 0 | I3: en México no reciben una tasa como sucede en US (IORB, interest rate on reserve balances)
B4: Títulos conservados a vencimiento | C4: =SUM(C5:C9) -> 670 | D4: =SUM(D5:D9) -> 980
B5: Bonos gubernamentales < 1 año (Nivel 1 para HQLA) | C5: 180 | D5: 160 | E5: 0.075 | F5: =E5*C5 -> 13.5 | I5: tasa promedio 7.5%, duración modificada 0.2
B6: Bondes 1-5 años (Nivel 1 para HQLA) | C6: 240 | D6: 120 | E6: =0.0674+0.0019 -> 0.0693 | F6: =E6*C6 -> 16.632 | H6: =C6*0.005 -> 1.2 | I6: tasa variable spread promedio de 19 basis, duración modificada 0.08 | N6: TIIE FONDEO
B7: Bonos M 1-5 años (Nivel 2A para HQLA) | C7: 150 | D7: 300 | E7: 0.085 | F7: =E7*C7 -> 12.75 | I7: tasa fija promedio del 8.5%, duración modificada 2.4
B8: Bonos corporativos calif AA- o superior tasa fija (Nivel 2A para HQLA) | C8: 100 | D8: 250 | E8: 0.09 | F8: =E8*C8 -> 9 | I8: tasa fija promedio del 9%, duración modificada 3.2
B9: Bonos corporativos calif BBB- a A+ tasa fija (nivel 2B para HQLA) | C9: 0 | D9: 150 | E9: 0.095 | F9: =E9*C9 -> 0 | I9: tasa fija promedio del 9.5%, duración modificada 2.9
B10: Cartera de crédito | C10: =SUM(C11:C15) -> 6500 | D10: =SUM(D11:D15) -> 6500
B11: Hipotecario | C11: 1500 | D11: 900 | E11: 0.1075 | F11: =E11*C11 -> 161.25 | I11: tasa fija promedio del 10.75% para el banco del Pacífico y del 11.50% para el banco del Golfo, duración modificada 8.3 para ambos
B12: Consumo (tarjetas de crédito, de nómina, personales) | C12: 2500 | D12: 1700 | E12: =0.6*(0.07+0.36)+0.4*(0.07+0.12) -> 0.334 | F12: =E12*C12 -> 835 | H12: =C12*0.6*0.005 -> 7.5 | I12: el 60% del Pacífico es tarjetas a TIIE+36%, el resto del Pacífico es fija promedio 19%, para el Golfo el 50% es tarjeta a TIIE+42% y lo demás es fija promedio 24%
B13: PYMES | C13: 800 | D13: 600 | E13: =0.07+0.09 -> 0.16 | F13: =E13*C13 -> 128 | H13: =C13*0.005 -> 4 | I13: tasa variable promedio de TIIE+9% para el banco del Pacífico y TIIE+12% para el banco del Golfo
B14: Corporativo (grandes empresas) | C14: 1200 | D14: 1900 | E14: =0.07+0.04 -> 0.11 | F14: =E14*C14 -> 132 | H14: =C14*0.005 -> 6 | I14: tasa variable promedio de TIIE+4% para el banco del Pacífico y TIIE+3% para el banco del Golfo
B15: Instituciones Financieras (sofoms, sofipos, sapis, otros bancos) | C15: 500 | D15: 1400 | E15: =0.07+0.03 -> 0.1 | F15: =E15*C15 -> 50 | H15: =C15*0.005 -> 2.5 | I15: tasa variable promedio de TIIE+3% para el banco del Pacífico y TIIE+2.5% para el banco del Golfo
B16: Activos Fijos | C16: 330 | D16: 270 | F16: =SUM(F3:F15) -> 1358.132 | H16: =SUM(H6:H15) -> 21.2
B17: Otros activos | C17: 48 | D17: 64
B18: TOTAL ACTIVO | C18: =C3+C4+C10+C16+C17 -> 7998 | D18: =D3+D4+D10+D16+D17 -> 8054
B19: Depósitos a la vista | C19: =C20+C21 -> 2700 | D19: =D20+D21 -> 3200 | I19: las tasas que pagan por depósitos a la vista, las actualizan en la medida que se mueve la tasa objetivo del banco central por un factor de 0.5
B20: Minoristas (retail)a | C20: 2100 | D20: 1400 | E20: 0.04 | F20: =C20*E20 -> 84 | H20: =C20*0.005*0.5 -> 5.25 | I20: han tenido que empezar a pagar en función del saldo promedio y de acuerdo al monto, Pacífico paga promedio ponderado 4% vs. 3% del Golfo
B21: De empresasb | C21: 600 | D21: 1800 | E21: 0.04 | F21: =C21*E21 -> 24 | H21: =C21*0.005*0.5 -> 1.5 | I21: misma situación dada la competencia de los neobancos, Pacífico paga en promedio 4% vs 5% del Golfo
B22: Depósitos a plazo | C22: =C23+C24 -> 2300 | D22: =D23+D24 -> 2300
B23: Minoristas (retail) | C23: 1900 | D23: 1200 | E23: 0.05 | F23: =C23*E23 -> 95 | H23: =C23*0.005 -> 9.5 | I23: Pacífico paga tasa promedio del 5% mientras que Golfo paga 4%, repricing mitad mensual y mitad trimestral
B24: De empresas | C24: 400 | D24: 1100 | E24: 0.0525 | F24: =C24*E24 -> 21 | H24: =C24*0.005 -> 2 | I24: Pacífico paga tasa ponderada de 5.25% mientras que Golfo paga 6%, repricing 3/4 partes mensual y 1/4 parte trimestral
B25: Fondeo mayoristac | C25: 750 | D25: 900 | E25: 0.065 | F25: =C25*E25 -> 48.75 | H25: =C25*0.005 -> 3.75 | I25: tasa promedio 6.5% el Pacífico y 6.75% el Golfo, repricing mitad semanal y mitad mensual
B26: Bonos emitidos con vencimiento < 1 año | C26: 400 | D26: 0 | E26: 0.07 | F26: =C26*E26 -> 28 | H26: =C26*0.005 -> 2 | I26: Tasa TIIE 28
B27: Bonos emitidos con vencimiento 1-5 años | C27: 1000 | D27: 500 | E27: 0.1 | F27: =C27*E27 -> 100 | I27: El cupón del Pacífico es 10% duración modificada 2.3, el cupón del Golfo es TIIE+1.25% duración modificada 0.08
B28: Bonos emitidos con vencimiento 5-10 años | C28: 0 | D28: 500 | E28: 0.0875 | F28: =C28*E28 -> 0 | I28: El cupón del Golfo es 8.75% duración modificada 6.4
B29: TOTAL PASIVO | C29: =C19+C22+C25+C26+C27+C28 -> 7150 | D29: =D19+D22+D25+D26+D27+D28 -> 7400 | F29: =SUM(F20:F28) -> 400.75 | H29: =SUM(H20:H28) -> 24
B30: Capital Tier 1d | C30: 848 | D30: 654
B31: Capital Tier 2e | C31: 0 | D31: 0
B32: TOTAL CAPITAL | C32: =C30+C31 -> 848 | D32: =D30+D31 -> 654
B33: TOTAL PASIVO Y CAPITAL | C33: =C29+C32 -> 7998 | D33: =D29+D32 -> 8054
