Workbook

Sheet Datos
B2: cifras en millones de pesos | C2: Banco de Occidente
B3: Efectivo y reservas en el banco central | C3: 860
B4: Títulos de deuda | C4: =SUM(C5:C11) -> 3000
B5: Bonos gubernamentales < 1 año (Nivel 1 para HQLA) | C5: 400 | D5: tasa del 7.25%
B6: Bonos gubernamentales 1-5 años tasa revisable (Nivel 1 para HQLA) | C6: 0 | D6: spread de 19 basis
B7: Bonos gubernamentales 1-5 años tasa fija (Nivel 2A para HQLA) | C7: 1000 | D7: tasa del 8.35%
B8: Bonos gubernamentales 5-10 años tasa flotante (Nivel 1 para HQLA) | C8: 0 | D8: spread de 34 basis
B9: Bonos gubernamentales 5-10 años tasa fija (Nivel 2A para HQLA) | C9: 1000 | D9: tasa del 8.65%
B10: Bonos corporativos calif AA- o superior tasa fija (Nivel 2A para HQLA) | C10: 600 | D10: tasa del 9.5%
B11: Bonos corporativos calif BBB- a A+ tasa fija (nivel 2B para HQLA) | C11: 0 | D11: tasa del 9.80%
B12: Cartera de crédito | C12: =SUM(C13:C17) -> 24141
B13: Hipotecario | C13: 4127 | D13: tasa del 11.20%
B14: Consumo (tarjetas de crédito, de nómina, personales)* | C14: 4892 | D14: tasa de TIIE28+50% para tarjetas, fija del 19% para nómina y fija del 23% para personales
B15: PYMES | C15: 6193 | D15: tasa de TIIE28 + 8%
B16: Corporativo (grandes empresas)** | C16: 6584 | D16: tasa de TIIE28 + 2.75% el 85% de los préstamos y TIIE91 + 3.25% el resto de estos préstamos
B17: Instituciones Financieras | C17: 2345 | D17: tasa de TIIE28 + 3% el 70% de estos préstamos y TIIE91 + 3.5% el restante
B18: Activos Fijos | C18: 1468
B19: Otros activos | C19: 64
B20: TOTAL ACTIVO | C20: =C3+C4+C12+C18+C19 -> 29533
B21: Depósitos a la vista | C21: =C22+C23 -> 5070
B22: Minoristas (retail)*** | C22: 2897 | D22: cero, no paga interés en este tipo de cuentas
B23: De empresas**** | C23: 2173 | D23: cero, no paga interés en este tipo de cuentas
B24: Depósitos a plazo | C24: =C25+C26 -> 5660
B25: Minoristas (retail)***** | C25: 3389 | D25: tasa de 4.25% para los que son a 1 mes, 4.75% para los que son a 3 meses, 5% para los que son a 6 meses y 5.25% para los que son a 1 año
B26: De empresas | C26: 2271 | D26: pagan un cuarto de punto más que las de persona física
B27: Fondeo mayorista****** | C27: 3549 | D27: tasa promedio del 7.00%
B28: Bonos emitidos con vencimiento < 1 año | C28: 0
B29: Bonos emitidos con vencimiento 1-5 años | C29: 2400 | D29: TIIE28 + 2%
B30: Bonos emitidos con vencimiento 5-10 años | C30: 3800 | D30: tasa del 9%
B31: TOTAL PASIVO | C31: =C21+C24+C27+C28+C29+C30 -> 20479
B32: Capital Tier 1 | C32: 4054
B33: Capital Tier 2 | C33: 5000 | D33: tasa del 12.5% para un bono convertible (CoCo) por 3 mil millones y del 11.5% para un bono perpetuo de 2 mil millones
B34: TOTAL CAPITAL | C34: =C32+C33 -> 9054
B35: TOTAL PASIVO Y CAPITAL | C35: =C31+C34 -> 29533
B37: * Del monto señalado, el 39% corresponde a tarjetas de crédito, el 32% a créditos de nómina y el porcentaje restante a créditos personales
B39: ** A los corporativos se les dan 2 tipos de créditos: revolventes y amortizables, éstos últimos pueden ser de 4 subtipos: bullet, ballon payment, pagos crecientes, pagos iguales
B41: *** Los depósitos minoristas se consideran 75% core o estables y 25% non-core o volátiles
B43: **** Los depósitos de empresas se consideran 45% de empresas financieras y 55% de empresas no-financieras
B44: De las empresas financieras, el 90% se consideran operativas y el 10% no operativas, de las NO-financieras el 60% se consideran operativas y el 40% no operativas
B46: ***** De los retail a plazo el 45% es a 1 mes, el 35% a 3 meses, el 15% a 6 meses y el restante a 1 año
...

Sheet LCR
B2: LCR | C2: =F11/G36 -> 0.77916145
B4: HQLA
C6: Descripción | D6: Ponderación | E6: Monto | F6: Monto Factorizado
C7: Efectivo y reservas en el banco central | D7: 1 | E7: =Datos!C3 -> 860 | F7: =E7*D7 -> 860
C8: Nivel 1 para HQLA | D8: 1 | E8: =Datos!C5 -> 400 | F8: =E8*D8 -> 400
C9: Nivel 2A para HQLA | D9: 0.85 | E9: =Datos!C7+Datos!C9+Datos!C10 -> 2600 | F9: =E9*D9 -> 2210
C10: Nivel 2B para HQLA | D10: 0.5 | E10: 0 | F10: =E10*D10 -> 0
E11: TOTAL | F11: =SUM(F7:F10) -> 3470
B13: SALIDAS NETAS DE EFECTIVO
C15: Descripción | D15: Factor | E15: Ponderaciones | F15: Monto | G15: Monto Factorizado
C16: VISTA
C17: Depósitos minoristas core (vista) | D17: 0.03 | E17: 0.75 | F17: =E17*Datos!C22 -> 2172.75 | G17: =F17*D17 -> 65.1825
C18: Depósitos minoristas menos estables (vista) | D18: 0.1 | E18: =1-E17 -> 0.25 | F18: =E18*Datos!C22 -> 724.25 | G18: =F18*D18 -> 72.425
C19: Depósitos operacionales de empresas (vista) | D19: 0.25 | E19: =0.55*0.6 -> 0.33 | F19: =E19*Datos!$C$23 -> 717.09 | G19: =F19*D19 -> 179.2725
C20: Depósitos no operacionales de empresas (vista) | D20: 0.4 | E20: =0.55*0.4 -> 0.22 | F20: =E20*Datos!$C$23 -> 478.06 | G20: =F20*D20 -> 191.224
C21: Depósitos operacioneles de financieras (vista) | D21: 1 | E21: =0.45*0.9 -> 0.405 | F21: =E21*Datos!$C$23 -> 880.065 | G21: =F21*D21 -> 880.065
C22: Depósitos no operacioneles de financieras (vista) | D22: 1 | E22: =0.45*0.1 -> 0.045 | F22: =E22*Datos!$C$23 -> 97.785 | G22: =F22*D22 -> 97.785
C23: PLAZO
C24: Depósitos minoristas core (plazo) | D24: 0.03 | E24: =E17 -> 0.75 | F24: =E24*Datos!C25 -> 2541.75 | G24: =F24*D24 -> 76.2525
C25: Depósitos minoristas menos estables (plazo) | D25: 0.1 | E25: =E18 -> 0.25 | F25: =E25*Datos!C25 -> 847.25 | G25: =F25*D25 -> 84.725
C26: Depósitos operacionales de empresas (plazo) | D26: 0.25 | E26: =E19 -> 0.33 | F26: =E26*Datos!$C$26 -> 749.43 | G26: =F26*D26 -> 187.3575
C27: Depósitos no operacionales de empresas (plazo) | D27: 0.4 | E27: =E20 -> 0.22 | F27: =E27*Datos!$C$26 -> 499.62 | G27: =F27*D27 -> 199.848
C28: Depósitos operacioneles de financieras (plazo) | D28: 1 | E28: =E21 -> 0.405 | F28: =E28*Datos!$C$26 -> 919.755 | G28: =F28*D28 -> 919.755
C29: Depósitos no operacioneles de financieras (plazo) | D29: 1 | E29: =E22 -> 0.045 | F29: =E29*Datos!$C$26 -> 102.195 | G29: =F29*D29 -> 102.195
C30: FONDEO MAYORISTA
C31: Fondeo mayorista garantizado con HQLA Nivel 1 contraparte no financiera | D31: 0 | E31: 0.1 | F31: =E31*Datos!$C$27 -> 354.9 | G31: =F31*D31 -> 0
C32: Fondeo mayorista garantizado con HQLA Nivel 1 contraparte financiera | D32: 0 | E32: 0 | F32: =E32*Datos!$C$27 -> 0 | G32: =F32*D32 -> 0
C33: Fondeo mayorista garantizado con HQLA Nivel 2A contraparte no financiera | D33: 0.15 | E33: 0 | F33: =E33*Datos!$C$27 -> 0 | G33: =F33*D33 -> 0
C34: Fondeo mayorista garantizado con HQLA Nivel 2A contraparte financiera | D34: 0.25 | E34: =0.9*0.75 -> 0.675 | F34: =E34*Datos!$C$27 -> 2395.575 | G34: =F34*D34 -> 598.89375
C35: Fondeo mayorista sin colateral (sin garantía) | D35: 1 | E35: =0.9*0.25 -> 0.225 | F35: =E35*Datos!$C$27 -> 798.525 | G35: =F35*D35 -> 798.525
F36: TOTAL | G36: =SUM(G17:G22,G24:G29,G31:G35) -> 4453.5058

Sheet NSFR
B2: NSFR | C2: =F18/F33 -> 1.5021741
B4: ASF
C6: Descripción | D6: Factor | E6: Monto | F6: Monto Factorizado
C7: Capital Tier 1 y Tier 2 | D7: 1 | E7: =Datos!C34 -> 9054 | F7: =D7*E7 -> 9054
C8: Pasivos con plazo residual mayor a 1 año | D8: 1 | E8: =Datos!C29+Datos!C30 -> 6200 | F8: =D8*E8 -> 6200
C9: Depósitos minoristas estables (core) | D9: 0.95 | E9: =LCR!F17+LCR!F24 -> 4714.5 | F9: =D9*E9 -> 4478.775
C10: Depósitos minoristas menos estables (volátiles) | D10: 0.9 | E10: =LCR!F18+LCR!F25 -> 1571.5 | F10: =D10*E10 -> 1414.35
C11: Depósitos operacionales de empresas no financieras | D11: 0.75 | E11: =LCR!F19+LCR!F26 -> 1466.52 | F11: =D11*E11 -> 1099.89
C12: Depósitos no operacionales de empresas no financieras | D12: 0 | E12: =LCR!F20+LCR!F27 -> 977.68 | F12: =D12*E12 -> 0
C13: Depósitos operacionales de empresas financieras | D13: 0.5 | E13: =LCR!F21+LCR!F28 -> 1799.82 | F13: =D13*E13 -> 899.91
C14: Depósitos no operacionales de empresas financieras | D14: 0 | E14: =LCR!F22+LCR!F29 -> 199.98 | F14: =D14*E14 -> 0
C15: Fondeo mayorista contrapartes no financieras con colateral | D15: 0.6 | E15: =LCR!F31+LCR!F33 -> 354.9 | F15: =D15*E15 -> 212.94
C16: Fondeo mayorista contrapartes financieras con colateral | D16: 0.4 | E16: =LCR!F32+LCR!F34 -> 2395.575 | F16: =D16*E16 -> 958.23
C17: Fondeo mayorista sin colateral | D17: 0 | E17: =LCR!F35 -> 798.525 | F17: =D17*E17 -> 0
E18: TOTAL | F18: =SUM(F7:F17) -> 24318.095
B21: RSF
C23: Descripción | D23: Factor | E23: Monto | F23: Monto Factorizado
C24: Efectivo y depósitos en el banco central | D24: 0 | E24: =LCR!E7 -> 860 | F24: =E24*D24 -> 0
C25: HQLA nivel 1 | D25: 0.05 | E25: =LCR!E8 -> 400 | F25: =E25*D25 -> 20
C26: HQLA nivel 2A | D26: 0.15 | E26: =SUM(LCR!E9:E9) -> 2600 | F26: =E26*D26 -> 390
C27: HQLA nivel 2B | D27: 0.5 | E27: =LCR!E10 -> 0 | F27: =E27*D27 -> 0
C28: Hipotecarios | D28: 0.65 | E28: =Datos!C13 -> 4127 | F28: =E28*D28 -> 2682.55
C29: Créditos a consumo | D29: 0.5 | E29: =Datos!C14 -> 4892 | F29: =E29*D29 -> 2446
C30: Créditos PYME | D30: 0.65 | E30: =Datos!C15 -> 6193 | F30: =E30*D30 -> 4025.45
C31: Créditos a empresas no financieras (corporativos) largo plazo | D31: 0.65 | E31: =Datos!C16 -> 6584 | F31: =E31*D31 -> 4279.6
C32: Créditos a instituciones financieras (largo plazo) | D32: 1 | E32: =Datos!C17 -> 2345 | F32: =E32*D32 -> 2345
E33: TOTAL | F33: =SUM(F24:F32) -> 16188.6

Sheet NII
C2: TIIE 28 | D2: 0.069971
C3: TIIE 91 | D3: 0.070371
C4: TIIE Fondeo | D4: 0.0674 | F4: Cambio en TIIE | G4: -0.01
C6: Total Ingresos | D6: =E28 -> 4243.4737 | F6: Total Ingresos | G6: =H28 -> -170.2988 | I6: Total Activos Variables | K6: =C15+C17+C24+C25+C26+C23*0.39 -> 17029.88
C7: Total Egresos | D7: =E44 -> 1671.8645 | F7: Total Egresos | G7: =H44 -> -78.9055 | I7: Total Pasivos Variables | K7: =0.95*C35+C36+C39 -> 7890.55
C8: NII | D8: =D6-D7 -> 2571.6091 | F8: Delta NII | G8: =G6-G7 -> -91.3933 | I8: Diff | K8: =K6-K7 -> 9139.33
C9: ROE | D9: =D8/C42 -> 0.63433871 | F9: Delta ROE | G9: =G8/C42 -> -0.022543981
B11: cifras en millones de pesos | C11: Banco de Occidente | D11: Tasa | E11: Ingresos | G11: Delta Tasa | H11: Delta Ingreso
B12: Efectivo y reservas en el banco central | C12: 860
B13: Títulos de deuda | C13: =SUM(C14:C20) -> 3000
B14: Bonos gubernamentales < 1 año (Nivel 1 para HQLA) | C14: 400 | D14: 0.0725 | E14: =C14*D14 -> 29 | G14: 0 | H14: =C14*G14 -> 0 | I14: tasa del 7.25%
B15: Bonos gubernamentales 1-5 años tasa revisable (Nivel 1 para HQLA) | C15: 0 | D15: =D4+0.0019 -> 0.0693 | E15: =C15*D15 -> 0 | G15: =G4 -> -0.01 | H15: =C15*G15 -> 0 | I15: spread de 19 basis
B16: Bonos gubernamentales 1-5 años tasa fija (Nivel 2A para HQLA) | C16: 1000 | D16: 0.0835 | E16: =C16*D16 -> 83.5 | G16: 0 | H16: =C16*G16 -> 0 | I16: tasa del 8.35%
B17: Bonos gubernamentales 5-10 años tasa flotante (Nivel 1 para HQLA) | C17: 0 | D17: =D4+0.0034 -> 0.0708 | E17: =C17*D17 -> 0 | G17: =G4 -> -0.01 | H17: =C17*G17 -> 0 | I17: spread de 34 basis
B18: Bonos gubernamentales 5-10 años tasa fija (Nivel 2A para HQLA) | C18: 1000 | D18: 0.0865 | E18: =C18*D18 -> 86.5 | G18: 0 | H18: =C18*G18 -> 0 | I18: tasa del 8.65%
B19: Bonos corporativos calif AA- o superior tasa fija (Nivel 2A para HQLA) | C19: 600 | D19: 0.095 | E19: =C19*D19 -> 57 | G19: 0 | H19: =C19*G19 -> 0 | I19: tasa del 9.5%
B20: Bonos corporativos calif BBB- a A+ tasa fija (nivel 2B para HQLA) | C20: 0 | D20: 0.098 | E20: =C20*D20 -> 0 | G20: 0 | H20: =C20*G20 -> 0 | I20: tasa del 9.80%
B21: Cartera de crédito | C21: =SUM(C22:C26) -> 24141
B22: Hipotecario | C22: 4127 | D22: 0.112 | E22: =C22*D22 -> 462.224 | G22: 0 | H22: =C22*G22 -> 0 | I22: tasa del 11.20%
B23: Consumo (tarjetas de crédito, de nómina, personales)* | C23: 4892 | D23: =0.39*(D2+0.5)+0.32*(0.19)+0.29*(0.23) -> 0.34978869 | E23: =C23*D23 -> 1711.1663 | G23: =G4*0.39 -> -0.0039 | H23: =C23*G23 -> -19.0788 | I23: tasa de TIIE28+50% para tarjetas, fija del 19% para nómina y fija del 23% para personales
B24: PYMES | C24: 6193 | D24: =D2+0.08 -> 0.149971 | E24: =C24*D24 -> 928.7704 | G24: =G4 -> -0.01 | H24: =C24*G24 -> -61.93 | I24: tasa de TIIE28 + 8%
B25: Corporativo (grandes empresas)** | C25: 6584 | D25: =0.85*(D2+0.0275)+0.15*(D3+0.0325) -> 0.098281 | E25: =C25*D25 -> 647.0821 | G25: =G4 -> -0.01 | H25: =C25*G25 -> -65.84 | I25: tasa de TIIE28 + 2.75% el 85% de los préstamos y TIIE91 + 3.25% el resto de estos préstamos
B26: Instituciones Financieras | C26: 2345 | D26: =0.7*(D2+0.03)+0.3*(D3+0.035) -> 0.101591 | E26: =C26*D26 -> 238.23089 | G26: =G4 -> -0.01 | H26: =C26*G26 -> -23.45 | I26: tasa de TIIE28 + 3% el 70% de estos préstamos y TIIE91 + 3.5% el restante
B27: Activos Fijos | C27: 1468
B28: Otros activos | C28: 64 | D28: TOTAL | E28: =SUM(E14:E26) -> 4243.4737 | G28: TOTAL | H28: =SUM(H14:H26) -> -170.2988
B30: TOTAL ACTIVO | C30: =C12+C13+C21+C27+C28 -> 29533 | D30: Tasa | E30: Egresos | G30: Delta Tasa | H30: Delta Egresos
B31: Depósitos a la vista | C31: =C32+C33 -> 5070
B32: Minoristas (retail)*** | C32: 2897 | D32: 0 | E32: =C32*D32 -> 0 | G32: 0 | H32: =C32*G32 -> 0 | I32: cero, no paga interés en este tipo de cuentas
B33: De empresas**** | C33: 2173 | D33: 0 | E33: =C33*D33 -> 0 | G33: 0 | H33: =C33*G33 -> 0 | I33: cero, no paga interés en este tipo de cuentas
B34: Depósitos a plazo | C34: =C35+C36 -> 5660
B35: Minoristas (retail)***** | C35: 3389 | D35: =0.45*(0.0425)+0.35*(0.0475)+0.15*(0.05)+0.05*(0.0525) -> 0.045875 | E35: =C35*D35 -> 155.47038 | G35: =G4*0.95 -> -0.0095 | H35: =C35*G35 -> -32.1955 | I35: tasa de 4.25% para los que son a 1 mes, 4.75% para los que son a 3 meses, 5% para los que son a 6 meses y 5.25% para los que son a 1 año
B36: De empresas | C36: 2271 | D36: =0.75*(0.0425+0.0025)+0.25*(0.0475+0.0025) -> 0.04625 | E36: =C36*D36 -> 105.03375 | G36: =G4 -> -0.01 | H36: =C36*G36 -> -22.71 | I36: pagan un cuarto de punto más que las de persona física
B37: Fondeo mayorista****** | C37: 3549 | D37: 0.07 | E37: =C37*D37 -> 248.43 | G37: 0 | H37: =C37*G37 -> 0 | I37: tasa promedio del 7.00%
B38: Bonos emitidos con vencimiento < 1 año | C38: 0
B39: Bonos emitidos con vencimiento 1-5 años | C39: 2400 | D39: =D2+0.02 -> 0.089971 | E39: =C39*D39 -> 215.9304 | G39: =G4 -> -0.01 | H39: =C39*G39 -> -24 | I39: TIIE28 + 2%
B40: Bonos emitidos con vencimiento 5-10 años | C40: 3800 | D40: 0.09 | E40: =C40*D40 -> 342 | G40: 0 | H40: =C40*G40 -> 0 | I40: tasa del 9%
B41: TOTAL PASIVO | C41: =C31+C34+C37+C38+C39+C40 -> 20479
B42: Capital Tier 1 | C42: 4054
B43: Capital Tier 2 | C43: 5000 | D43: =0.6*(0.125)+0.4*(0.115) -> 0.121 | E43: =C43*D43 -> 605 | G43: 0 | H43: =C43*G43 -> 0 | I43: tasa del 12.5% para un bono convertible (CoCo) por 3 mil millones y del 11.5% para un bono perpetuo de 2 mil millones
B44: TOTAL CAPITAL | C44: =C42+C43 -> 9054 | D44: TOTAL | E44: =SUM(E32:E43) -> 1671.8645 | G44: TOTAL | H44: =SUM(H32:H43) -> -78.9055
...
