Workbook

Sheet Equipo
B13: Administración de Riesgos
B14: Proyecto Final
B15: Equipo:
B16: Isabela Torres- Septien Uribe
B17: Samuel Gomez Jimenez
B18: Regina Espinoza Preciado
B19: Ana Paula Moreno Haro
B20: Prof:
B21: Abrham Oceguera Gomez
B22: 46157

Sheet Credito Simple
A1: Num préstamo | B1: Saldo insoluto (en millones de pesos | C1: Mensualidades (remaining) para el vencimiento | D1: Tasa de interés | E1: Prob. Impago | F1: Severidad | G1: b1 | H1: b2 | I1: b3
A2: 1 | B2: 15 | C2: 45 | D2: 0.25 | E2: 0.023 | F2: 0.45 | G2: 0.34 | H2: 0.24 | I2: 0.42
A3: 2 | B3: 17 | C3: 31 | D3: 0.23 | E3: 0.024 | F3: 0.45 | G3: 0.26 | H3: 0.34 | I3: 0.4
A4: 3 | B4: 12 | C4: 55 | D4: TIIEF + 8% | E4: 0.02 | F4: 0.45 | G4: 0.19 | H4: 0.44 | I4: 0.37
A5: 4 | B5: 7 | C5: 58 | D5: TIIEF + 9% | E5: 0.024 | F5: 0.33 | G5: 0.25 | H5: 0.3 | I5: 0.45
A6: 5 | B6: 14 | C6: 60 | D6: TIIEF + 10% | E6: 0.028 | F6: 0.45 | G6: 0.2 | H6: 0.36 | I6: 0.44
A7: 6 | B7: 12 | C7: 32 | D7: 0.25 | E7: 0.023 | F7: 0.45 | G7: 0.33 | H7: 0.39 | I7: 0.28
A8: 7 | B8: 18 | C8: 48 | D8: 0.26 | E8: 0.024 | F8: 0.45 | G8: 0.23 | H8: 0.38 | I8: 0.39
A9: 8 | B9: 14 | C9: 30 | D9: 0.23 | E9: 0.017 | F9: 0.45 | G9: 0.32 | H9: 0.21 | I9: 0.47
A10: 9 | B10: 13 | C10: 39 | D10: TIIEF + 10% | E10: 0.028 | F10: 0.45 | G10: 0.23 | H10: 0.25 | I10: 0.52
A11: 10 | B11: 18 | C11: 47 | D11: TIIEF + 10% | E11: 0.027 | F11: 0.45 | G11: 0.16 | H11: 0.34 | I11: 0.5
A12: 11 | B12: 10 | C12: 54 | D12: 0.27 | E12: 0.037 | F12: 0.33 | G12: 0.31 | H12: 0.23 | I12: 0.46
A13: 12 | B13: 19 | C13: 54 | D13: 0.27 | E13: 0.038 | F13: 0.45 | G13: 0.22 | H13: 0.24 | I13: 0.54
A14: 13 | B14: 6 | C14: 46 | D14: TIIEF+6% | E14: 0.01 | F14: 0.33 | G14: 0.16 | H14: 0.45 | I14: 0.39
A15: 14 | B15: 11 | C15: 35 | D15: TIIEF+9% | E15: 0.025 | F15: 0.45 | G15: 0.22 | H15: 0.32 | I15: 0.46
A16: 15 | B16: 16 | C16: 36 | D16: TIIEF+9% | E16: 0.023 | F16: 0.45 | G16: 0.17 | H16: 0.3 | I16: 0.53
A17: 16 | B17: 17 | C17: 49 | D17: TIIEF+10% | E17: 0.028 | F17: 0.45 | G17: 0.3 | H17: 0.43 | I17: 0.27
A18: 17 | B18: 9 | C18: 60 | D18: 0.21 | E18: 0.017 | F18: 0.33 | G18: 0.31 | H18: 0.29 | I18: 0.4
A19: 18 | B19: 14 | C19: 46 | D19: 0.28 | E19: 0.037 | F19: 0.45 | G19: 0.33 | H19: 0.27 | I19: 0.4
A20: 19 | B20: 10 | C20: 58 | D20: 0.26 | E20: 0.029 | F20: 0.33 | G20: 0.19 | H20: 0.37 | I20: 0.44
A21: 20 | B21: 5 | C21: 33 | D21: 0.19 | E21: 0.011 | F21: 0.33 | G21: 0.16 | H21: 0.28 | I21: 0.56
A22: 21 | B22: 7 | C22: 28 | D22: TIIEF+8% | E22: 0.033 | F22: 0.33 | G22: 0.35 | H22: 0.35 | I22: 0.3
A23: 22 | B23: 6 | C23: 32 | D23: TIIEF+6% | E23: 0.012 | F23: 0.33 | G23: 0.35 | H23: 0.3 | I23: 0.35
A24: 23 | B24: 8 | C24: 36 | D24: 0.18 | E24: 0.012 | F24: 0.33 | G24: 0.15 | H24: 0.3 | I24: 0.55
A25: 24 | B25: 3 | C25: 21 | D25: TIIEF+7% | E25: 0.018 | F25: 0.33 | G25: 0.24 | H25: 0.37 | I25: 0.39
A26: 25 | B26: 7 | C26: 10 | D26: 0.19 | E26: 0.014 | F26: 0.33 | G26: 0.26 | H26: 0.25 | I26: 0.49
A27: 26 | B27: 8 | C27: 10 | D27: 0.24 | E27: 0.037 | F27: 0.33 | G27: 0.24 | H27: 0.37 | I27: 0.39
A28: 27 | B28: 3 | C28: 18 | D28: 0.18 | E28: 0.014 | F28: 0.33 | G28: 0.35 | H28: 0.27 | I28: 0.38
A29: 28 | B29: 9 | C29: 18 | D29: 0.23 | E29: 0.036 | F29: 0.33 | G29: 0.32 | H29: 0.41 | I29: 0.27
A30: 29 | B30: 3 | C30: 21 | D30: 0.23 | E30: 0.035 | F30: 0.33 | G30: 0.15 | H30: 0.22 | I30: 0.63
A31: 30 | B31: 11 | C31: 29 | D31: TIIEF+8% | E31: 0.04 | F31: 0.45 | G31: 0.33 | H31: 0.21 | I31: 0.46
A32: 31 | B32: 12 | C32: 32 | D32: TIIEF+7% | E32: 0.032 | F32: 0.45 | G32: 0.31 | H32: 0.38 | I32: 0.31
A33: 32 | B33: 12 | C33: 34 | D33: TIIEF+6% | E33: 0.025 | F33: 0.45 | G33: 0.25 | H33: 0.22 | I33: 0.53
A34: 33 | B34: 4 | C34: 11 | D34: TIIEF+6% | E34: 0.02 | F34: 0.33 | G34: 0.32 | H34: 0.25 | I34: 0.43
A35: 34 | B35: 12 | C35: 25 | D35: TIIEF+7% | E35: 0.028 | F35: 0.45 | G35: 0.2 | H35: 0.2 | I35: 0.6
A36: 35 | B36: 7 | C36: 12 | D36: TIIEF+6% | E36: 0.022 | F36: 0.33 | G36: 0.33 | H36: 0.38 | I36: 0.29
A37: 36 | B37: 11 | C37: 26 | D37: 0.21 | E37: 0.026 | F37: 0.45 | G37: 0.28 | H37: 0.26 | I37: 0.46
A38: 37 | B38: 3 | C38: 24 | D38: 0.23 | E38: 0.033 | F38: 0.33 | G38: 0.32 | H38: 0.45 | I38: 0.23
A39: 38 | B39: 4 | C39: 16 | D39: 0.25 | E39: 0.033 | F39: 0.33 | G39: 0.27 | H39: 0.32 | I39: 0.41
A40: 39 | B40: 5 | C40: 24 | D40: 0.24 | E40: 0.036 | F40: 0.33 | G40: 0.24 | H40: 0.21 | I40: 0.55
...

Sheet Credito Revolvente
A1: Num préstamo | B1: Límite de Crédito (millones de pesos) | C1: Monto Dispuesto (millones de pesos) | D1: Prob. Impago | E1: Severidad | F1: b1 | G1: b2 | H1: b3 | I1: sobretasa | J1: es lo que en total se le suma a la TIIEF
A2: 1 | B2: 5 | C2: 1 | D2: 0.017 | E2: 0.67 | F2: 0.3 | G2: 0.37 | H2: 0.33 | I2: 0.04 | J2: 400 basis
A3: 2 | B3: 5 | C3: 4 | D3: 0.036 | E3: 0.75 | F3: 0.34 | G3: 0.25 | H3: 0.41 | I3: 0.05 | J3: 500 basis
A4: 3 | B4: 5 | C4: 3 | D4: 0.027 | E4: 0.75 | F4: 0.3 | G4: 0.44 | H4: 0.26 | I4: 0.05
A5: 4 | B5: 5 | C5: 2 | D5: 0.056 | E5: 0.67 | F5: 0.29 | G5: 0.33 | H5: 0.38 | I5: 0.05
A6: 5 | B6: 10 | C6: 7 | D6: 0.048 | E6: 0.75 | F6: 0.31 | G6: 0.38 | H6: 0.31 | I6: 0.05
A7: 6 | B7: 10 | C7: 8 | D7: 0.022 | E7: 0.75 | F7: 0.25 | G7: 0.26 | H7: 0.49 | I7: 0.04
A8: 7 | B8: 10 | C8: 10 | D8: 0.054 | E8: 0.75 | F8: 0.28 | G8: 0.43 | H8: 0.29 | I8: 0.05
A9: 8 | B9: 5 | C9: 3 | D9: 0.057 | E9: 0.75 | F9: 0.32 | G9: 0.29 | H9: 0.39 | I9: 0.05
A10: 9 | B10: 5 | C10: 2 | D10: 0.028 | E10: 0.67 | F10: 0.34 | G10: 0.32 | H10: 0.34 | I10: 0.05
A11: 10 | B11: 10 | C11: 10 | D11: 0.056 | E11: 0.75 | F11: 0.27 | G11: 0.42 | H11: 0.31 | I11: 0.05
A12: 11 | B12: 5 | C12: 1 | D12: 0.036 | E12: 0.67 | F12: 0.34 | G12: 0.45 | H12: 0.21 | I12: 0.05
A13: 12 | B13: 5 | C13: 2 | D13: 0.023 | E13: 0.67 | F13: 0.29 | G13: 0.42 | H13: 0.29 | I13: 0.04
A14: 13 | B14: 5 | C14: 1 | D14: 0.045 | E14: 0.67 | F14: 0.25 | G14: 0.35 | H14: 0.4 | I14: 0.05
A15: 14 | B15: 5 | C15: 1 | D15: 0.055 | E15: 0.67 | F15: 0.35 | G15: 0.42 | H15: 0.23 | I15: 0.05
... A87: 86 | B87: 5 | C87: 4 | D87: 0.056 | E87: 0.75 | F87: 0.34 | G87: 0.36 | H87: 0.3 | I87: 0.05

Sheet Balance
B2: cifras en millones de pesos
B3: Efectivo y reservas en el banco central | C3: -
B4: HQLA (Activos líquidos de alta calidad) | C4: 140
B5: Reportos 1 día — colateral gubernamental (Nivel 1 para HQLA) | C5: 50
B6: Reportos 7 días — colateral bancario (Nivel 2A para HQLA) | C6: 50
B7: Bonos M con vencimiento en 2029 (Nivel 1 para HQLA) | C7: 40
B8: Cartera de crédito | C8: =C9+C10 -> 862
B9: Crédito simple amortizable a PYMEs y PFAEs (64 créditos) | C9: =SUM('Credito Simple'!B2:B65) -> 479
B10: Crédito revolvente — monto dispuesto (86 créditos) | C10: =SUM('Credito Revolvente'!C2:C87) -> 383
B11: Activos Fijos | C11: 32
B12: Otros activos | C12: -
B13: TOTAL ACTIVO | C13: =C4+C8+C11 -> 1034
B14: Depósitos a la vista | C14: -
B15: Depósitos a plazo | C15: -
B16: Préstamos bancarios | C16: =C17+C18+C19 -> 210
B17: Banco 1 — TIIEF+3.5%, amortizable, vence en 12 meses | C17: 50
B18: Banco 2 — TIIEF+4.0%, amortizable, vence en 18 meses | C18: 60
B19: Banco 3 — TIIEF+2.75%, amortizable, vence en 36 meses | C19: 100
B20: Préstamos de inversionistas institucionales | C20: =C21+C22 -> 300
B21: Fondo private credit 1 — 17% fija, bullet 6 meses | C21: 100
B22: Fondo private credit 2 — 19% fija, bullet 24 meses | C22: 200
B23: Certificados bursátiles (cebures) emitidos | C23: -
B24: TOTAL PASIVO | C24: =C16+C20 -> 510
B25: Capital social (aportaciones de accionistas) | C25: 400
B26: Utilidades retenidas | C26: 124
B27: TOTAL CAPITAL | C27: =C25+C26 -> 524
B28: TOTAL PASIVO Y CAPITAL | C28: =C24+C27 -> 1034

Sheet LCR
B2: HQLA
B4: Descripción | C4: Factor | D4: Monto | E4: Monto Factorizado
B5: Efectivo y reservas en el banco central | C5: 1 | D5: 0 | E5: =C5*D5 -> 0
B6: Nivel 1 para HQLA | C6: 1 | D6: 50 | E6: =C6*D6 -> 50
B7: Nivel 1 para HQLA | C7: 1 | D7: 40 | E7: =C7*D7 -> 40
B8: Nivel 2B para HQLA | C8: 0.85 | D8: 50 | E8: =C8*D8 -> 42.5
D9: TOTAL | E9: =SUM(E5:E8) -> 132.5
B11: SALIDAS NETAS DE EFECTIVO
B13: Descripción | C13: Factor | D13: Monto | E13: Monto Factorizado
B14: Banco 1 | C14: 1 | D14: =Balance!C17/12 -> 4.1666667 | E14: =D14*C14 -> 4.1666667
B15: Banco 2 | C15: 1 | D15: =Balance!C18/18 -> 3.3333333 | E15: =D15*C15 -> 3.3333333
B16: Banco 3 | C16: 1 | D16: =Balance!C19/36 -> 2.7777778 | E16: =D16*C16 -> 2.7777778
D17: TOTAL | E17: =SUM(E14:E16) -> 10.277778
B19: Resultado LCR | C19: =E9/E17 -> 12.891892
B20: Por encima del minimo regulatorio

Sheet NSFR
B2: ASF
B4: Descripción | C4: Factor | D4: Monto | E4: Monto Factorizado
B5: Capital Social | C5: 1 | D5: 400 | E5: =D5*C5 -> 400
B6: Utilidadesd retenidas | C6: 1 | D6: 124 | E6: =D6*C6 -> 124
B7: Banco 3 | C7: 1 | D7: 100 | E7: =D7*C7 -> 100
B8: Banco 2 | C8: 1 | D8: 60 | E8: =D8*C8 -> 60
B9: Banco 1 | C9: 0.5 | D9: 50 | E9: =D9*C9 -> 25
B10: Fondo institucional 1 — vence en 6m (residual < 1 año, financiero) | C10: 0 | D10: 100 | E10: =D10*C10 -> 0
B11: Préstamos institucionales — residual > 1 año (Fondo 2: 200, plazo 24m) | C11: 1 | D11: 200 | E11: =D11*C11 -> 200
D12: TOTAL | E12: =SUM(E5:E11) -> 909
B14: RSF
B16: Descripción | C16: Factor | D16: Monto | E16: Monto Factorizado
B17: HQLA nivel 1 | C17: 0.05 | D17: 50 | E17: =C17*D17 -> 2.5
B18: Bonos M | C18: 0.05 | D18: 40 | E18: =C18*D18 -> 2
B19: HQLA nivel 2A | C19: 0.15 | D19: 50 | E19: =C19*D19 -> 7.5
B20: Créditos PYME | C20: 0.65 | D20: 479 | E20: =C20*D20 -> 311.35
B21: Créditos revolventes | C21: 0.5 | D21: 383 | E21: =C21*D21 -> 191.5
B22: Activos fijos/fisicos | C22: 0.01 | D22: 32 | E22: =C22*D22 -> 0.32
B23: Otros activos | C23: 0.01 | D23: 0 | E23: =C23*D23 -> 0
D24: TOTAL | E24: =SUM(E17:E23) -> 515.17
B26: Resultado NSFR | C26: =E12/E24 -> 1.7644661
B27: Por encima del minimo regulatorio

Sheet Gap Liquidez
B2: Descripción | C2: ≤1m | D2: 1-3m | E2: 3-6m | F2: 6-12m | G2: 1-2a | H2: 2-3a | I2: >3a | J2: TOTAL
B3: INFLOWS (Cobros)
B4: Cartera simple amortizable (64 créditos) | C4: =SUMIF('Credito Simple'!C2:C365, "=1", 'Credito Simple'!B2:B65) -> 0 | D4: =SUMIF('Credito Simple'!C2:C365, "<=3", 'Credito Simple'!B2:B65)-C4 -> 9 | E4: =SUMIF('Credito Simple'!C2:C365,"<=6",'Credito Simple'!B2:B65)-SUM(C4:D4) -> 24 | F4: =SUMIF('Credito Simple'!C2:C365,"<=12",'Credito Simple'!B2:B65)-SUM(C4:E4) -> 49 | G4: =SUMIF('Credito Simple'!C2:C365, "<=24", 'Credito Simple'!B2:B65)-SUM(C4:F4) -> 37 | H4: =SUMIF('Credito Simple'!C2:C365,"<=36",'Credito Simple'!B2:B65)-SUM(C4:G4) -> 178 | I4: =SUMIF('Credito Simple'!C2:C365, ">36", 'Credito Simple'!B2:B65) -> 182 | J4: =SUM(C4:I4) -> 479
B5: Crédito revolvente — monto dispuesto (86 créditos) | C5: =SUM('Credito Revolvente'!C2:C87)/3 -> 127.66667 | D5: =C5*2 -> 255.33333 | E5: 0 | F5: 0 | G5: 0 | H5: 0 | I5: 0 | J5: =SUM(C5:I5) -> 383
B6: TOTAL INFLOWS | C6: =C4+C5 -> 127.66667 | D6: =D4+D5 -> 264.33333 | E6: =E4+E5 -> 24 | F6: =F4+F5 -> 49 | G6: =G4+G5 -> 37 | H6: =H4+H5 -> 178 | I6: =I4+I5 -> 182 | J6: =SUM(C6:I6) -> 862
B7: OUTFLOWS (Pagos de fondeo)
B8: Banco 1 — TIIEF+3.5% | C8: =50/12 -> 4.1666667 | D8: =C8*2 -> 8.3333333 | E8: =C8*3 -> 12.5 | F8: =C8*6 -> 25 | G8: 0 | H8: 0 | I8: 0 | J8: =SUM(C8:I8) -> 50
B9: Banco 2 — TIIEF+4.0% | C9: =60/18 -> 3.3333333 | D9: =C9*2 -> 6.6666667 | E9: =C9*3 -> 10 | F9: =C9*6 -> 20 | G9: =C9*6 -> 20 | H9: 0 | I9: 0 | J9: =SUM(C9:I9) -> 60
B10: Banco 3 — TIIEF+2.75% | C10: =100/36 -> 2.7777778 | D10: =C10*2 -> 5.5555556 | E10: =C10*3 -> 8.3333333 | F10: =C10*6 -> 16.666667 | G10: =C10*12 -> 33.333333 | H10: =G10 -> 33.333333 | I10: 0 | J10: =SUM(C10:I10) -> 100
B11: Fondo private 1 — 17% fija | C11: 0 | D11: 0 | E11: 100 | F11: 0 | G11: 0 | H11: 0 | I11: 0 | J11: =SUM(C11:I11) -> 100
B12: Fondo private 2 — 19% fija | C12: 0 | D12: 0 | E12: 0 | F12: 0 | G12: 200 | H12: 0 | I12: 0 | J12: =SUM(C12:I12) -> 200
B13: TOTAL OUTFLOWS | C13: =SUM(C8:C12) -> 10.277778 | D13: =SUM(D8:D12) -> 20.555556 | E13: =SUM(E8:E12) -> 130.83333 | F13: =SUM(F8:F12) -> 61.666667 | G13: =SUM(G8:G12) -> 253.33333 | H13: =SUM(H8:H12) -> 33.333333 | I13: =SUM(I8:I12) -> 0 | J13: =SUM(C13:I13) -> 510
B14: GAP (Inflows − Outflows) | C14: =C6-C13 -> 117.38889 | D14: =D6-D13 -> 243.77778 | E14: =E6-E13 -> -106.83333 | F14: =F6-F13 -> -12.666667 | G14: =G6-G13 -> -216.33333 | H14: =H6-H13 -> 144.66667 | I14: =I6-I13 -> 182 | J14: =SUM(C14:I14) -> 352
B15: GAP ACUMULADO | C15: =C14 -> 117.38889 | D15: =C15+D14 -> 361.16667 | E15: =D15+E14 -> 254.33333 | F15: =E15+F14 -> 241.66667 | G15: =F15+G14 -> 25.333333 | H15: =G15+H14 -> 170 | I15: =H15+I14 -> 352
B17: Interpretación
B18: El gap de liquidez de la sofom muestra holgura en el corto plazo (≤1m y 1-3m positivos por $117M y $244M, impulsados por el revolvente) y en el largo plazo (>2 años positivos por la maduración de la cartera amortizable), pero presenta descalces importantes en las bandas intermedias: -$107M en 3-6m por el bullet del fondo private 1 ($100M al 17%), -$13M en 6-12m, y el peor punto en 1-2a con -$216M por el bullet del fondo private 2 ($200M al 19%) más amortizaciones del Banco 2. El GAP acumulado se mantiene positivo en todas las bandas pero toca un mínimo muy delgado de $25M en 1-2a, lo que evidencia que el problema no es de monto sino de calendario: los cobros llegan tarde y los pagos grandes (los dos bullets de private credit) llegan temprano, generando un riesgo de refinanciamiento concentrado que conviene mitigar con la emisión escalonada del cebur o líneas comprometidas de respaldo.

Sheet Gap Tasas
B2: Descripción | C2: Tasa Variable (TIIEF +)
B3: ACTIVOS SENSIBLES A TASA | E3: Tiene exposiión a alza o baja de tasas
B4: Crédito simple — Tasa variable (TIIEF+) | C4: ='Credito Simple'!B4+'Credito Simple'!B5+'Credito Simple'!B6+'Credito Simple'!B10+'Credito Simple'!B11+'Credito Simple'!B14+'Credito Simple'!B15+'Credito Simple'!B16+'Credito Simple'!B17+'Credito Simple'!B22+'Credito Simple'!B23+'Credito Simple'!B25+'Credito Simple'!B31+'Credito Simple'!B32+'Credito Simple'!B33+'Credito Simple'!B34+'Credito Simple'!B35+'Credito Simple'!B36+'Credito Simple'!B47+'Credito Simple'!B48+'Credito Simple'!B49+'Credito Simple'!B50+'Credito Simple'!B51+'Credito Simple'!B52+'Credito Simple'!B53+'Credito Simple'!B54+'Credito Simple'!B55+'Credito Simple'!B56+'Credito Simple'!B57+'Credito Simple'!B58+'Credito Simple'!B59+'Credito Simple'!B60+'Credito Simple'!B61+'Credito Simple'!B62+'Credito Simple'!B63+'Credito Simple'!B64+'Credito Simple'!B65 -> 244 | E4: La sofom presenta un gap de tasas positivo de +517 mdp (activos sensibles a TIIEF de 727 mdp contra pasivos sensibles de solo 210 mdp), lo que significa que tiene significativamente más activos que pasivos re-preciables ante movimientos de la tasa de referencia. Esto lo coloca como ASSET SENSITIVE, posición que la expone directamente a una baja de tasas.
B5: Crédito simple — Tasa fija | C5: 0
B6: Crédito revolvente — Monto dispuesto (todo TIIEF+) | C6: 383
B7: Reportos 1 día — col. gubernamental (Nivel 1) | C7: 50
B8: Reportos 7 días — col. bancario (Nivel 2A) | C8: 50
B9: Bonos M vencimiento 2029 (Nivel 1) | C9: 0 | E9: Mantenemos la estructura actual?
B10: TOTAL ACTIVOS | C10: =SUM(C4:C9) -> 727 | E10: Mantener la estructura actual no es recomendable. Si bien el gap positivo resulta favorable en un entorno de alzas de tasas, el ciclo actual apunta en sentido contrario ante la anticipación del ciclo de recortes de Banxico, y la concentración de activos a tasa variable sin una cobertura equivalente en el pasivo genera una asimetría que podría erosionar el margen financiero.
B11: PASIVOS SENSIBLES A TASA
B12: Banco 1 — TIIEF+3.5% | C12: 50
B13: Banco 2 — TIIEF+4.0% | C13: 60
B14: Banco 3 — TIIEF+2.75% | C14: 100
B15: Fondo private 1 — 17% fija | C15: 0 | E15: Como la modificarias
B16: Fondo private 2 — 19% fija | C16: 0 | E16: Se recomienda una estrategia de cobertura en dos frentes. Primero, contratar un IRS receive-fixed / pay-floating (SWAP RECEIVER) sobre un nocional equivalente o parcial al GAP de tasas a un plazo de 2–3 años, convirtiendo sintéticamente parte de la cartera variable en flujos fijos sin modificar los contratos con los clientes. Segundo, aprovechar la emisión de cebures planeada (1,000 mdp) para emitir 500 mdp a tasa fija y 500 mdp a tasa variable, lo que incrementa el RSL y cierra parte del gap de forma estructural.
B17: TOTAL PASIVOS | C17: =SUM(C12:C16) -> 210
B18: GAP (Activos − Pasivos)
B19: GAP de Tasas | C19: =C10-C17 -> 517

Sheet VaR Crédito
B2: Expected Shortfall | C2: 187.8
B3: VaR de crédito | C3: 142.51
B4: Expected Loss | C4: 14.73
B5: UCL | C5: =142.51-14.73 -> 127.78
B17: Capital real aportado | C17: 400
B18: utilidades reinvertidas | C18: 124
B19: Capital total | C19: =C17+C18 -> 524
B20: UCL | C20: =C5 -> 127.78
B21: Excedente | C21: =C19-C20 -> 396.22 | D21: Cumple la regulación

Sheet VaR HQLA
A1: Fecha de operación | B1: 31 May 2029 | C1: Delta PB | D1: P&L
A2: 31/05/2024 | B2: 9.89 | F2: Monto Invertido | G2: 40000000
A3: 03/06/2024 | B3: 9.93 | C3: =(B3-B2)*100 -> 4 | D3: =-C3*$G$8 -> -42289.978 | F3: Cantidad de Títulos | G3: =G2/G5 -> 397462.2
A4: 04/06/2024 | B4: 10.04 | C4: =(B4-B3)*100 -> 11 | D4: =-C4*$G$8 -> -116297.44 | F4: Posición | G4: LONG
A5: 05/06/2024 | B5: 9.98 | C5: =(B5-B4)*100 -> -6 | D5: =-C5*$G$8 -> 63434.968 | F5: Precio | G5: 100.6385
A6: 06/06/2024 | B6: 9.88 | C6: =(B6-B5)*100 -> -10 | D6: =-C6*$G$8 -> 105724.95 | F6: Precio con delta 1PB | G6: 100.6651
A7: 07/06/2024 | B7: 9.95 | C7: =(B7-B6)*100 -> 7 | D7: =-C7*$G$8 -> -74007.462 | F7: PV01 x Bono | G7: =G6-G5 -> 0.0266
A8: 10/06/2024 | B8: 10.24 | C8: =(B8-B7)*100 -> 29 | D8: =-C8*$G$8 -> -306602.34 | F8: PV01 x Posición | G8: =G3*G7 -> 10572.495
A9: 11/06/2024 | B9: 10.33 | C9: =(B9-B8)*100 -> 9 | D9: =-C9*$G$8 -> -95152.452
A10: 12/06/2024 | B10: 10.46 | C10: =(B10-B9)*100 -> 13 | D10: =-C10*$G$8 -> -137442.43 | F10: VaR - 99% | G10: =PERCENTILE(D3:D489,0.01) -> -149495.07
A11: 13/06/2024 | B11: 10.37 | C11: =(B11-B10)*100 -> -9 | D11: =-C11*$G$8 -> 95152.452 | F11: CVaR - 99% | G11: =AVERAGEIF(D3:D489,"<"&G10) -> -209335.39
A12: 14/06/2024 | B12: 10.19 | C12: =(B12-B11)*100 -> -18 | D12: =-C12*$G$8 -> 190304.9
A13: 17/06/2024 | B13: 10.29 | C13: =(B13-B12)*100 -> 10 | D13: =-C13*$G$8 -> -105724.95 | F13: https://www.banxico.org.mx/valores/PresentaDetallePosicionGub.faces?BMXC_instrumento=2&BMXC_lang=es_MX
A14: 18/06/2024 | B14: 10.3 | C14: =(B14-B13)*100 -> 1 | D14: =-C14*$G$8 -> -10572.495 | F14: https://www.banxico.org.mx/mercsecd/index.html?tabla=N&locale=es_ES
A15: 19/06/2024 | B15: 10.18 | C15: =(B15-B14)*100 -> -12 | D15: =-C15*$G$8 -> 126869.94
A16: 20/06/2024 | B16: 10.19 | C16: =(B16-B15)*100 -> 1 | D16: =-C16*$G$8 -> -10572.495 | F16: Justificación del tratamiento de los reportos en el cálculo de VaR de mercado
A17: 21/06/2024 | B17: 10.13 | C17: =(B17-B16)*100 -> -6 | D17: =-C17*$G$8 -> 63434.968 | F17: Tratamiento de los reportos en el VaR de mercado. De los $140 millones en HQLA, $100 millones están invertidos en reportos con colateral a plazos de 1 día (fondeo gubernamental) y 7 días (fondeo bancario), los cuales se consideran exentos de riesgo de mercado material para efectos de este cálculo. La duración modificada de estas posiciones es prácticamente nula (0.0028 y 0.0194 años, respectivamente) y su PV01 combinado representaría una sensibilidad inmaterial incluso ante movimientos extremos de la curva de fondeo, que además es poco volátil al estar anclada a la tasa objetivo de Banxico. Adicionalmente, las operaciones están respaldadas por colateral con haircut, por lo que el riesgo asociado corresponde a contraparte y no a mercado direccional. En consecuencia, el cálculo del VaR y Expected Shortfall de mercado del portafolio HQLA se concentra exclusivamente en los $40 millones del bono M 2029, donde reside la totalidad del riesgo de tasas materialmente medible.
A18: 24/06/2024 | B18: 10.09 | C18: =(B18-B17)*100 -> -4 | D18: =-C18*$G$8 -> 42289.978
A19: 25/06/2024 | B19: 10.05 | C19: =(B19-B18)*100 -> -4 | D19: =-C19*$G$8 -> 42289.978
A20: 26/06/2024 | B20: 10.06 | C20: =(B20-B19)*100 -> 1 | D20: =-C20*$G$8 -> -10572.495
A21: 27/06/2024 | B21: 10.03 | C21: =(B21-B20)*100 -> -3 | D21: =-C21*$G$8 -> 31717.484
A22: 28/06/2024 | B22: 9.97 | C22: =(B22-B21)*100 -> -6 | D22: =-C22*$G$8 -> 63434.968
A23: 01/07/2024 | B23: 10.01 | C23: =(B23-B22)*100 -> 4 | D23: =-C23*$G$8 -> -42289.978
A24: 02/07/2024 | B24: 10.09 | C24: =(B24-B23)*100 -> 8 | D24: =-C24*$G$8 -> -84579.957
A25: 03/07/2024 | B25: 10.1 | C25: =(B25-B24)*100 -> 1 | D25: =-C25*$G$8 -> -10572.495
A26: 04/07/2024 | B26: 10.06 | C26: =(B26-B25)*100 -> -4 | D26: =-C26*$G$8 -> 42289.978
A27: 05/07/2024 | B27: 10.08 | C27: =(B27-B26)*100 -> 2 | D27: =-C27*$G$8 -> -21144.989
A28: 08/07/2024 | B28: 10.07 | C28: =(B28-B27)*100 -> -1 | D28: =-C28*$G$8 -> 10572.495
A29: 09/07/2024 | B29: 10.09 | C29: =(B29-B28)*100 -> 2 | D29: =-C29*$G$8 -> -21144.989
... A489: 13/05/2026 | B489: 8.24 | C489: =(B489-B488)*100 -> 0 | D489: =-C489*$G$8 -> 0

Sheet Propuestas
B2: Propuesta 1: Cubrir el riesgo de tasas con un swap y emitir el cebur mixto
B3: El gap de tasas da +$517 mdp (activos sensibles por $727 mdp contra pasivos sensibles por solo $210 mdp), o sea que la sofom es claramente asset sensitive y le pega una baja de tasas. Como Banxico ya está empezando con el ciclo de recortes, mantener la estructura tal cual va a ir comiéndose el margen poco a poco. Lo que se propone es atacarlo por dos lados. Primero, contratar un IRS donde la sofom reciba fija y pague variable, por un nocional de entre $300 y $400 mdp a 2 o 3 años. Esto hace que parte de la cartera variable se comporte como si fuera fija, sin tener que tocar los contratos con los clientes. Segundo, cuando se emita el cebur, hacerlo mitad fijo y mitad variable en lugar de todo a una sola tasa. Con esto los pasivos sensibles aumentan y el gap se cierra desde el balance, no nada más con el derivado. Combinando las dos medidas, el +$517 mdp se reduce bastante y el balance queda más parejo ante movimientos en cualquier dirección.
B15: Propuesta 2: Refinanciar los bullets con la emisión del cebur
B16: El gap de liquidez deja ver que el peor problema está en la banda de 1-2 años, donde hay un faltante de -$216 mdp por el vencimiento bullet del Fondo 2 ($200 mdp al 19%). El otro punto débil está en 3-6 meses (-$107 mdp) por el bullet del Fondo 1 ($100 mdp al 17%). Los dos son los pasivos más caros que tiene la sofom y los dos vencen de golpe, así que el riesgo de refinanciamiento se junta justo cuando hay menos cobros entrando. La propuesta es usar la emisión de cebures de $1,000 mdp que ya tienen planeada para reemplazar estos dos bullets antes de su vencimiento. Lo dividiríamos así: $300 mdp a 3 años para pagar el Fondo 1, y $700 mdp a 5 años amortizable para pagar el Fondo 2. Como las sofoms suelen colocar cebures a tasas mucho más bajas que el costo de los fondos institucionales (que están al 17 y 19%), no solo se cierra el hueco sino que también se baja el costo financiero y mejora el margen. Como respaldo, también convendría tener una línea de crédito comprometida con algún banco por unos $150 mdp, por si la ventana de emisión se cierra justo cuando se necesita salir al mercado.
B28: Propuesta 3: Bajar el requerimiento de capital sacando los créditos más riesgosos
B29: El VaR de crédito al 99% es $142.5 mdp y la UCL $127.78 mdp. El capital total que tiene la sofom ($524 mdp) los cubre sin problema, pero tener ese capital amarrado limita el crecimiento y baja el ROE. La idea es revisar la cartera (tanto amortizable como revolvente) e identificar los créditos con PD mayor o igual a 3%, que son los que más están pesando en la UCL. Estos se pueden sacar del balance ya sea cediéndolos a otra sofom o, si el monto lo justifica, armando un CLO con tramos equity, mezzanine, junior y senior. Los mismos fondos de private credit que hoy fondean a la sofom podrían entrarle a los tramos mezzanine y junior, que es justo el tipo de riesgo que les gusta. Con esto bajan las UCL, baja el capital regulatorio requerido, y queda capital libre para colocar más cartera nueva pero de mejor calidad. Además convendría poner un límite por cliente (por ejemplo, que ningún crédito sea más del 2% de la cartera total) para que un solo default no mueva tanto la UCL.
