Workbook

Sheet escala credit risk rating
C4: AAA | D4: máxima calificación crediticia (más seguro)
C5: AA+
C6: AA
C7: AA-
C8: A+
C9: A
C10: A-
C11: BBB+
C12: BBB
C13: BBB- | D13: de aquí hacia arriba es grado de inversión (investment grade), y hacia abajo es grado especulativo (high yield)
C14: BB+
C15: BB
C16: BB-
C17: B+
C18: B
C19: B-
C20: CCC | D20: calificación crediticia más baja (más riesgosa, a un paso del default)
C21: D

Sheet factores LCR y NSFR
B2: LCR HQLA | C2: Tipo de activo | D2: Ponderación
B3: Nivel 1 | C3: Efectivo y reservas en el banco central | D3: 1 | E3: sin haircut
B4: Nivel 1 | C4: Bonos gubernamentales < 1 año o duración menor a 1 | D4: 1 | E4: sin haircut
B5: Nivel 2A | C5: Bonos soberanos >1 año | D5: 0.85 | E5: haircut del 15%
B6: Nivel 2A | C6: Bonos corporativos calif AA- o superior | D6: 0.85 | E6: haircut del 15%
B7: Nivel 2B | C7: Bonos corporativos calif BBB- a A+ | D7: 0.5 | E7: haircut del 50%
A10: LCR | B10: Salidas (pasivos) factores de run-off a 30 días
C11: Depósitos minoristas core (vista y plazo) | D11: 0.03
C12: Depósitos minoristas menos estables (vista y plazo) | D12: 0.1
C13: Depósitos operacionales de empresas (vista y plazo) | D13: 0.25
C14: Depósitos no operacionales de empresas (vista y plazo) | D14: 0.4
C15: Depósitos no operacioneles de financieras (vista y plazo) | D15: 1
C17: Fondeo mayorista garantizado con HQLA Nivel 1 | D17: 0
C18: Fondeo mayorista garantizado con HQLA Nivel 2A contraparte no financiera | D18: 0.15
C19: Fondeo mayorista garantizado con HQLA Nivel 2A contraparte financiera | D19: 0.25
C20: Fondeo mayorista sin colateral (sin garantía) | D20: 1
B23: NSFR Factores para ASF (available stable funding)
C24: Capital Tier 1 y Tier 2 | D24: 1 | E24: lo más estable y disponible
C25: Pasivos con plazo residual mayor a 1 año | D25: 1 | E25: bonos emitidos, deuda subordinada
C26: Depósitos minoristas estables (core) | D26: 0.95 | E26: alta retención histórica (estadísticas)
C27: Depósitos minoristas menos estables (volátiles) | D27: 0.9 | E27: menor retención esperada
C28: Depósitos operacionales de empresas no financieras | D28: 0.75 | E28: relación operacional con el banco parcialmente estable
C29: Depósitos no operacionales de empresas no financieras | D29: 0 | E29: altamente volátil, no aporta fondeo estable
C30: Depósitos operacionales de empresas financieras | D30: 0.5 | E30: relación operacional con el banco parcialmente estable
C31: Depósitos no operacionales de empresas financieras | D31: 0 | E31: altamente volátil, no aporta fondeo estable
C32: Fondeo mayorista contrapartes no financieras con colateral | D32: 0.6 | E32: estabilidad relativa
C33: Fondeo mayorista contrapartes financieras con colateral | D33: 0.4 | E33: estabilidad relativa
C34: Fondeo mayorista sin colateral | D34: 0 | E34: altamente volátil, no aporta fondeo estable
B36: NSFR Factores para RSF (required stable funding)
C37: Efectivo y depósitos en el banco central | D37: 0
C38: HQLA nivel 1 | D38: 0.05
C39: HQLA nivel 2A | D39: 0.15
C40: HQLA nivel 2B | D40: 0.5
C41: Hipotecarios | D41: 0.65
C42: Créditos a consumo | D42: 0.5
C43: Créditos PYME | D43: 0.65
C44: Créditos a empresas no financieras (corporativos) largo plazo | D44: 0.65
C45: Créditos a instituciones financieras (largo plazo) | D45: 1

Sheet balances (banking book)
B3: cifras en millones de pesos | C3: Banco del Pacífico | D3: Banco del Golfo
B4: Efectivo y reservas en el banco central | C4: 450 | D4: 240 | E4: en México no reciben una tasa como sucede en US (IORB, interest rate on reserve balances)
B5: Títulos conservados a vencimiento | C5: =SUM(C6:C10) -> 670 | D5: =SUM(D6:D10) -> 980
A6: =C6*0.075 -> 13.5 | B6: Bonos gubernamentales < 1 año (Nivel 1 para HQLA) | C6: 180 | D6: 160 | E6: tasa promedio 7.5%, duración modificada 0.2
A7: =C7*(0.0674+0.0019) -> 16.632 | B7: Bondes 1-5 años (Nivel 1 para HQLA) | C7: 240 | D7: 120 | E7: tasa variable spread promedio de 19 basis, duración modificada 0.08
A8: =C8*0.085 -> 12.75 | B8: Bonos M 1-5 años (Nivel 2A para HQLA) | C8: 150 | D8: 300 | E8: tasa fija promedio del 8.5%, duración modificada 2.4
A9: =C9*0.09 -> 9 | B9: Bonos corporativos calif AA- o superior tasa fija (Nivel 2A para HQLA) | C9: 100 | D9: 250 | E9: tasa fija promedio del 9%, duración modificada 3.2
A10: =C10*0.095 -> 0 | B10: Bonos corporativos calif BBB- a A+ tasa fija (nivel 2B para HQLA) | C10: 0 | D10: 150 | E10: tasa fija promedio del 9.5%, duración modificada 2.9
B11: Cartera de crédito | C11: =SUM(C12:C16) -> 6500 | D11: =SUM(D12:D16) -> 6500
A12: =C12*0.1075 -> 161.25 | B12: Hipotecario | C12: 1500 | D12: 900 | E12: tasa fija promedio del 10.75% para el banco del Pacífico y del 11.50% para el banco del Golfo, duración modificada 8.3 para ambos
A13: =(C13*0.6*0.43)+(C13*0.4*0.19) -> 835 | B13: Consumo (tarjetas de crédito, de nómina, personales) | C13: 2500 | D13: 1700 | E13: el 60% del Pacífico es tarjetas a TIIE+36%, el resto del Pacífico es fija promedio 19%, para el Golfo el 50% es tarjeta a TIIE+42% y lo demás es fija promedio 24%
A14: =C14*0.16 -> 128 | B14: PYMES | C14: 800 | D14: 600 | E14: tasa variable promedio de TIIE+9% para el banco del Pacífico y TIIE+12% para el banco del Golfo
A15: =C15*0.11 -> 132 | B15: Corporativo (grandes empresas) | C15: 1200 | D15: 1900 | E15: tasa variable promedio de TIIE+4% para el banco del Pacífico y TIIE+3% para el banco del Golfo
A16: =C16*0.1 -> 50 | B16: Instituciones Financieras (sofoms, sofipos, sapis, otros bancos) | C16: 500 | D16: 1400 | E16: tasa variable promedio de TIIE+3% para el banco del Pacífico y TIIE+2.5% para el banco del Golfo
B17: Activos Fijos | C17: 330 | D17: 270
B18: Otros activos | C18: 48 | D18: 64
B19: TOTAL ACTIVO | C19: =C4+C5+C11+C17+C18 -> 7998 | D19: =D4+D5+D11+D17+D18 -> 8054
B20: Depósitos a la vista | C20: =C21+C22 -> 2700 | D20: =D21+D22 -> 3200 | E20: las tasas que pagan por depósitos a la vista, las actualizan en la medida que se mueve la tasa objetivo del banco central por un factor de 0.5
A21: =C21*0.04 -> 84 | B21: Minoristas (retail)a | C21: 2100 | D21: 1400 | E21: han tenido que empezar a pagar en función del saldo promedio y de acuerdo al monto, Pacífico paga promedio ponderado 4% vs. 3% del Golfo
A22: =C22*0.04 -> 24 | B22: De empresasb | C22: 600 | D22: 1800 | E22: misma situación dada la competencia de los neobancos, Pacífico paga en promedio 4% vs 5% del Golfo
B23: Depósitos a plazo | C23: =C24+C25 -> 2300 | D23: =D24+D25 -> 2300
A24: =C24*0.05 -> 95 | B24: Minoristas (retail) | C24: 1900 | D24: 1200 | E24: Pacífico paga tasa promedio del 5% mientras que Golfo paga 4%, repricing mitad mensual y mitad trimestral
A25: =C25*0.0525 -> 21 | B25: De empresas | C25: 400 | D25: 1100 | E25: Pacífico paga tasa ponderada de 5.25% mientras que Golfo paga 6%, repricing 3/4 partes mensual y 1/4 parte trimestral
A26: =C26*0.065 -> 48.75 | B26: Fondeo mayoristac | C26: 750 | D26: 900 | E26: tasa promedio 6.5% el Pacífico y 6.75% el Golfo, repricing mitad semanal y mitad mensual
A27: =C27*0.07 -> 28 | B27: Bonos emitidos con vencimiento < 1 año | C27: 400 | D27: 0 | E27: tasa TIIE28
A28: =C28*0.1 -> 100 | B28: Bonos emitidos con vencimiento 1-5 años | C28: 1000 | D28: 500 | E28: El cupón del Pacífico es 10% duración modificada 2.3, el cupón del Golfo es TIIE+1.25% duración modificada 0.08
A29: =C29 -> 0 | B29: Bonos emitidos con vencimiento 5-10 años | C29: 0 | D29: 500 | E29: El cupón del Golfo es 8.75% duración modificada 6.4
B30: TOTAL PASIVO | C30: =C20+C23+C26+C27+C28+C29 -> 7150 | D30: =D20+D23+D26+D27+D28+D29 -> 7400
B31: Capital Tier 1d | C31: 848 | D31: 654
B32: Capital Tier 2e | C32: 0 | D32: 0
B33: TOTAL CAPITAL | C33: =C31+C32 -> 848 | D33: =D31+D32 -> 654
B34: TOTAL PASIVO Y CAPITAL | C34: =C30+C33 -> 7998 | D34: =D30+D33 -> 8054

Sheet notas importantes
B2: (a) Para el Banco del Pacífico dado su enfoque en personas físicas (minorista) el 60% de sus depósitos se consideran estables o core y el 40% se consideran volátiles o menos estables
B3: mientras que para el Banco del Golfo dado su enfoque más en personas morales, el 30% de esos depósitos se consideran estables o core y el 70% se consideran menos estables
B5: (b) Para el Pacífico, el 20% de esos depósitos se consideran "operacionales" de empresa y el 80% se consideran "no operacionales" de empresa
B6: Para el Golfo, el 70% de esos depósitos son considerados "operacionales" de empresa y el 30% "no operacionales" de empresa
B8: (c) las contrapartes en el fondeo mayorista son empresas financieras, algunos con colateral y otros sin colateral
B9: En el caso de Banco del Pacífico, todo es con contrapartes financieras, la mitad con colateral Nivel 1 y la otra mitad sin colateral
B10: En el caso de Banco del Golfo, el 50% es con contrapartes financieras sin garantía, otro 30% con contrapartes financieras con colateral Nivel 2A y 20% con contrapartes no financieras con colateral Nivel 1
B12: (d) El Capital Tier 1 son principalmente 3 componentes: capital aportado por los socios, capital ganando conocido como utilidades retenidas, reservas de capital
B14: (e) El Capital Tier 2 son principalmente 2 componentes: bonos perpetuos (sin vencimiento) pero que pagan un cupón trimestral o semestral, y bonos convertibles a acciones (Contingent Convertibles)

Sheet Preguntas
B2: Riesgo de Liquidez a corto plazo: LCR
B3: ¿Cuál es el LCR de cada banco? Cumplen con el requisito regulario (mayor a 1.0) ? En caso de que no ¿cómo lo arreglarías?
B4: LCR del Banco del Pacífico = HQLA / Salidas netas a 30 días | C4: =D11/E26 -> 1.1079836 | D4: cumple con el mínimo
B5: Efectivo y reservas en el banco central | C5: 450 | D5: =C5*1 -> 450
B6: Bonos gubernamentales < 1 año (Nivel 1 para HQLA) | C6: 180 | D6: =C6*1 -> 180
B7: Bondes 1-5 años (Nivel 1 para HQLA) | C7: 240 | D7: =C7*1 -> 240
B8: Bonos M 1-5 años (Nivel 2A para HQLA) | C8: 150 | D8: =C8*0.85 -> 127.5
B9: Bonos corporativos calif AA- o superior tasa fija (Nivel 2A para HQLA) | C9: 100 | D9: =C9*0.85 -> 85
B10: Bonos corporativos calif BBB- a A+ tasa fija (nivel 2B para HQLA) | C10: 0 | D10: =C10*0.5 -> 0
D11: =SUM(D5:D10) -> 1082.5 | E11: esto voy a utilizar en el numerador para calcular el LCR de este banco (Pacífico)
B13: Salidas (pasivos) run-off a 30 días | E13: lo que proyecto/espero que salga de cada pasivo a un horizonte de 30 días
B14: Depósitos a la vista retail (pf) core | C14: =2100*0.6 -> 1260 | D14: 0.03 | E14: =C14*D14 -> 37.8
B15: Depósitos a la vista retail (pf) no estables, volátiles | C15: =2100*0.4 -> 840 | D15: 0.1 | E15: =C15*D15 -> 84
B16: Depósitos a la vista empresas (pm) operacional | C16: =600*0.2 -> 120 | D16: 0.25 | E16: =C16*D16 -> 30
B17: Depósitos a la vista empresas (pm) no operacional o volátil | C17: =600*0.8 -> 480 | D17: 0.4 | E17: =C17*D17 -> 192
B18: Depósitos a plazo retail (pf) core | C18: =1900*0.6 -> 1140 | D18: 0.03 | E18: =C18*D18 -> 34.2
B19: Depósitos a plazo retail (pf) volátil | C19: =1900*0.4 -> 760 | D19: 0.1 | E19: =C19*D19 -> 76
B20: Depósitos a plazo empresas(pm) operacional | C20: =400*0.2 -> 80 | D20: 0.25 | E20: =C20*D20 -> 20
B21: Depósitos a plazo empresas(pm) no operacional | C21: =400*0.8 -> 320 | D21: 0.4 | E21: =C21*D21 -> 128
E22: =C22*D22 -> 0
B23: Fondeo mayorista con colateral Nivel1 | C23: =750*0.5 -> 375 | D23: 0 | E23: =C23*D23 -> 0
B24: Fondeo mayorista SIN colateral | C24: =750*0.5 -> 375 | D24: 1 | E24: =C24*D24 -> 375
E26: =SUM(E14:E24) -> 977 | F26: salidas netas a 30 días
B27: Riesgo de Liquidez a largo plazo: NSFR
B28: ¿Cuál es el NSFR de cada banco? Cumplen con la regulación (mayor a 1.0) ? En caso contrario ¿qué propones para corregirlo? | G28: =E43/E55 -> 1.4370026 | H28: NO necesito hacer nada, ya cumple
B29: NSFR de Banco del Pacífico = Available Stable Funding o Fondeo Estable Disponible / Required Stable Funding o Requerimientos de Fondeo Estable
B31: Capital Tier 1 y Tier 2 | C31: 1 | D31: 848 | E31: =D31*C31 -> 848
B32: Pasivos con plazo residual mayor a 1 año | C32: 1 | D32: 1000 | E32: =D32*C32 -> 1000
B33: Depósitos minoristas estables (core) | C33: 0.95 | D33: =C14+C18 -> 2400 | E33: =D33*C33 -> 2280
B34: Depósitos minoristas menos estables (volátiles) | C34: 0.9 | D34: =C15+C19 -> 1600 | E34: =D34*C34 -> 1440
B35: Depósitos operacionales de empresas no financieras | C35: 0.75 | D35: =C16+C20 -> 200 | E35: =D35*C35 -> 150
B36: Depósitos no operacionales de empresas no financieras | C36: 0 | D36: =C17+C21 -> 800 | E36: =D36*C36 -> 0
B37: Depósitos operacionales de empresas financieras | C37: 0.5 | D37: 0 | E37: =D37*C37 -> 0
B38: Depósitos no operacionales de empresas financieras | C38: 0 | D38: 0 | E38: =D38*C38 -> 0
B39: Fondeo mayorista contrapartes no financieras con colateral | C39: 0.6 | D39: 0 | E39: =D39*C39 -> 0
B40: Fondeo mayorista contrapartes financieras con colateral | C40: 0.4 | D40: =C23 -> 375 | E40: =D40*C40 -> 150
B41: Fondeo mayorista sin colateral | C41: 0 | D41: =C24 -> 375 | E41: =D41*C41 -> 0
D43: =SUMPRODUCT(C31:C41,D31:D41) -> 5868 | E43: =SUM(E31:E41) -> 5868 | F43: esta cantidad es mi ASF o Fondeo Estable Disponible
B45: Efectivo y depósitos en el banco central | C45: 0 | D45: =C5 -> 450 | E45: =D45*C45 -> 0
B46: HQLA nivel 1 | C46: 0.05 | D46: =C6+C7 -> 420 | E46: =D46*C46 -> 21
...
